<?xml version="1.0"?>
<robot xmlns:xacro="http://www.ros.org/wiki/xacro" name="mower">
   
   <xacro:include filename="include.xacro" />
   <xacro:include filename="inertial_macros.xacro" />

   <link name="world"></link>

   <joint name="base_joint" type="fixed">
        <origin xyz="0.4572 0.3048 0" rpy="0 0 0"/>
        <parent link="world"/>
        <child link="base_link"/>        
   </joint>

  <link name="base_link">
        <visual>
            <origin xyz="0 0 0.05" rpy="0 0 0"/>
            <geometry>
                <box size="0.9144 0.6096 0.03175" />
            </geometry>
            <material name="blue">
                <color rgba="0.2 0.2 1 1"/>
            </material>
        </visual>
        <collision>
            <origin xyz="0 0 0.05" rpy="0 0 0"/>
            <geometry>
                <box size="0.9144 0.6096 0.03175" />
            </geometry>
        </collision>
        <xacro:inertial_box mass="0.5" x="0.9144" y="0.6096" z="0.03175">
            <origin xyz="0 0 0.05" rpy="0 0 0"/>
        </xacro:inertial_box>
    </link>

    <joint name="wheel_fr_joint" type="continuous">
        <origin xyz="0.4572 0.3048 0" rpy="${pi/2} 0 0"/>
        <axis xyz="0 0 -1"/>
        <parent link="base_link"/>
        <child link="wheel_fr_link"/>       
    </joint>

    <joint name="wheel_fl_joint" type="continuous">
        <origin xyz="0.4572 0.3048 0" rpy="-${pi/2} 0 0"/>
        <axis xyz="0 0 1"/>
        <parent link="base_link"/>
        <child link="wheel_fl_link"/>       
    </joint>

    <joint name="wheel_rr_joint" type="continuous">
        <origin xyz="0.4572 0.3048 0" rpy="${pi/2} 0 0"/>
        <axis xyz="0 0 -1"/>
        <parent link="base_link"/>
        <child link="wheel_rr_link"/>       
    </joint>

    <joint name="wheel_rl_joint" type="continuous">
        <origin xyz="0.4572 0.3048 0" rpy="-${pi/2} 0 0"/>
        <axis xyz="0 0 1"/>
        <parent link="base_link"/>
        <child link="wheel_rl_link"/>       
    </joint>

    <link name="wheel_fr_link">
        <visual>
            <origin xyz="0 0 0" rpy="0 0 0"/>
            <geometry>
                <cylinder length="0.0508" radius="0.1016" />
            </geometry>
            <material name="green">
                <color rgba="0.2 1 0.2 1"/>
            </material>
        </visual>
        <collision>
            <origin xyz="0 0 0" rpy="0 0 0"/>
            <geometry>
                <cylinder length="0.0508" radius="0.1016" />
            </geometry>
        </collision>
        <inertial>
            <origin xyz="0 0 0" rpy="0 0 0"/>
            <mass value="12" />
            <inertia ixx="2.26" ixy="0.0" ixz="0.0" iyy="6.26" iyz="0.0" izz="8.5" />
        </inertial>
    </link>

    <link name="wheel_fl_link">
        <visual>
            <origin xyz="0 0 0" rpy="0 0 0"/>
            <geometry>
                <cylinder length="0.0508" radius="0.1016" />
            </geometry>
            <material name="green">
                <color rgba="0.2 1 0.2 1"/>
            </material>
        </visual>
        <collision>
            <origin xyz="0 0 0" rpy="0 0 0"/>
            <geometry>
                <cylinder length="0.0508" radius="0.1016" />
            </geometry>
        </collision>
        <inertial>
            <origin xyz="0 0 0" rpy="0 0 0"/>
            <mass value="12" />
            <inertia ixx="2.26" ixy="0.0" ixz="0.0" iyy="6.26" iyz="0.0" izz="8.5" />
        </inertial>
    </link>

    <link name="wheel_rr_link">
        <visual>
            <origin xyz="0 0 0" rpy="0 0 0"/>
            <geometry>
                <cylinder length="0.0508" radius="0.1016" />
            </geometry>
            <material name="green">
                <color rgba="0.2 1 0.2 1"/>
            </material>
        </visual>
        <collision>
            <origin xyz="0 0 0" rpy="0 0 0"/>
            <geometry>
                <cylinder length="0.0508" radius="0.1016" />
            </geometry>
        </collision>
        <inertial>
            <origin xyz="0 0 0" rpy="0 0 0"/>
            <mass value="12" />
            <inertia ixx="2.26" ixy="0.0" ixz="0.0" iyy="6.26" iyz="0.0" izz="8.5" />
        </inertial>
    </link>

    <link name="wheel_rl_link">
        <visual>
            <origin xyz="0 0 0" rpy="0 0 0"/>
            <geometry>
                <cylinder length="0.0508" radius="0.1016" />
            </geometry>
            <material name="green">
                <color rgba="0.2 1 0.2 1"/>
            </material>
        </visual>
        <collision>
            <origin xyz="0 0 0" rpy="0 0 0"/>
            <geometry>
                <cylinder length="0.0508" radius="0.1016" />
            </geometry>
        </collision>
        <inertial>
            <origin xyz="0 0 0" rpy="0 0 0"/>
            <mass value="12" />
            <inertia ixx="2.26" ixy="0.0" ixz="0.0" iyy="6.26" iyz="0.0" izz="8.5" />
        </inertial>
    </link>

</robot>